Workbook

Sheet Instruções
B2: Ficha de Depósito no Zenodo — Rede Interseccional de Resiliência (RIR ALC)
B3: Projeto ALERTA-INTERSEC · Chamada MCTI/CNPq nº 02/2026 — PROSUL Pepe Mujica, Faixa B · Processo 445280/2026-3 · Contemplado em outubro de 2026
B5: Como usar
B6: 1) Abra a aba "Ficha de Depósito" e crie uma linha por produto;
B7: 2) A coluna ID Interno deve ser única e seguir o padrão RIR-AAAA-NNN (ex: RIR-2026-001);
B8: 3) Registre cada autoria na aba "Autoria", vinculando pelo ID Interno;
B9: 4) A aba "Validação" aponta automaticamente o que está pendente;
B10: 5) Só faça o upload no Zenodo quando a aba "Validação" indicar "Pronto para depósito".
B12: Regras obrigatórias
B13: Todo produto precisa de DOI antes de qualquer divulgação;
B14: ORCID é obrigatório para toda autoria;
B15: A licença padrão é CC BY 4.0; outra licença exige justificativa registrada no Comitê Gestor Interinstitucional;
... B25: Esta planilha é instrumento interno de trabalho. Não publique nem compartilhe fora da equipe, pois contém dados de contato e identificadores pessoais de pesquisadores.

Sheet Ficha de Depósito
A1: ID Interno | B1: Tipo de Recurso | C1: Título (Português) | D1: Título (Espanhol) | E1: Título (Inglês) | F1: Financiador | G1: Programa | H1: Processo | I1: Palavra-chave Principal | J1: Palavras-chave Adicionais | K1: Idioma do Arquivo | L1: Idioma dos Metadados | M1: Licença | N1: Justificativa da Licença | O1: Versão | P1: Acesso | Q1: Embargo até | R1: DOI de Produto Relacionado | S1: Técnica de Agregação Aplicada | T1: Declara Ausência de Dado Pessoal Identificável | U1: Contém Dado Sensível | V1: Parecer CEP/CONEP | W1: Status do Fluxo | X1: Responsável pelo Depósito | Y1: Data do Depósito | Z1: DOI Conceito | AA1: DOI de Versão | AB1: Conferência Automática
F2: Conselho Nacional de Desenvolvimento Científico e Tecnológico — CNPq | G2: PROSUL Pepe Mujica — Chamada MCTI/CNPq nº 02/2026, Faixa B | H2: 445280/2026-3 | O2: 1.0 | AB2: =IF(A2="","",IF(COUNTA($B2:$E2,$I2,$K2:$M2,$W2)=0,"Linha vazia",IF(COUNTA($B2:$E2,$I2,$K2:$M2)<8,"Campos obrigatórios pendentes: tipo, títulos PT/ES/EN, palavra-chave, idioma, licença",IF(AND($B2="Artigo",$E2=""),"Título em inglês obrigatório para artigo",IF(AND($M2="Outra — justificar",$N2=""),"Justificar a licença escolhida",IF(AND($P2="Embargo",$Q2=""),"Informar data de fim do embargo",IF($T2<>"Sim","Declarar ausência de dado pessoal identificável",IF($U2="Sim — vedado o depósito","Depósito vedado: contém dado sensível",IF(AND($B2="Conjunto de dados",$S2="Não se aplica"),"Conjunto de dados exige técnica de agregação declarada",IF($W2="Em preparação","Metadados ainda em preparação",IF(AND($W2="Publicado",$AA2=""),"Registrar o DOI de versão","Pronto para depósito")))))))))))
F3: Conselho Nacional de Desenvolvimento Científico e Tecnológico — CNPq | G3: PROSUL Pepe Mujica — Chamada MCTI/CNPq nº 02/2026, Faixa B | H3: 445280/2026-3 | O3: 1.0 | AB3: =IF(A3="","",IF(COUNTA($B3:$E3,$I3,$K3:$M3,$W3)=0,"Linha vazia",IF(COUNTA($B3:$E3,$I3,$K3:$M3)<8,"Campos obrigatórios pendentes: tipo, títulos PT/ES/EN, palavra-chave, idioma, licença",IF(AND($B3="Artigo",$E3=""),"Título em inglês obrigatório para artigo",IF(AND($M3="Outra — justificar",$N3=""),"Justificar a licença escolhida",IF(AND($P3="Embargo",$Q3=""),"Informar data de fim do embargo",IF($T3<>"Sim","Declarar ausência de dado pessoal identificável",IF($U3="Sim — vedado o depósito","Depósito vedado: contém dado sensível",IF(AND($B3="Conjunto de dados",$S3="Não se aplica"),"Conjunto de dados exige técnica de agregação declarada",IF($W3="Em preparação","Metadados ainda em preparação",IF(AND($W3="Publicado",$AA3=""),"Registrar o DOI de versão","Pronto para depósito")))))))))))
F4: Conselho Nacional de Desenvolvimento Científico e Tecnológico — CNPq | G4: PROSUL Pepe Mujica — Chamada MCTI/CNPq nº 02/2026, Faixa B | H4: 445280/2026-3 | O4: 1.0 | AB4: =IF(A4="","",IF(COUNTA($B4:$E4,$I4,$K4:$M4,$W4)=0,"Linha vazia",IF(COUNTA($B4:$E4,$I4,$K4:$M4)<8,"Campos obrigatórios pendentes: tipo, títulos PT/ES/EN, palavra-chave, idioma, licença",IF(AND($B4="Artigo",$E4=""),"Título em inglês obrigatório para artigo",IF(AND($M4="Outra — justificar",$N4=""),"Justificar a licença escolhida",IF(AND($P4="Embargo",$Q4=""),"Informar data de fim do embargo",IF($T4<>"Sim","Declarar ausência de dado pessoal identificável",IF($U4="Sim — vedado o depósito","Depósito vedado: contém dado sensível",IF(AND($B4="Conjunto de dados",$S4="Não se aplica"),"Conjunto de dados exige técnica de agregação declarada",IF($W4="Em preparação","Metadados ainda em preparação",IF(AND($W4="Publicado",$AA4=""),"Registrar o DOI de versão","Pronto para depósito")))))))))))
F5: Conselho Nacional de Desenvolvimento Científico e Tecnológico — CNPq | G5: PROSUL Pepe Mujica — Chamada MCTI/CNPq nº 02/2026, Faixa B | H5: 445280/2026-3 | O5: 1.0 | AB5: =IF(A5="","",IF(COUNTA($B5:$E5,$I5,$K5:$M5,$W5)=0,"Linha vazia",IF(COUNTA($B5:$E5,$I5,$K5:$M5)<8,"Campos obrigatórios pendentes: tipo, títulos PT/ES/EN, palavra-chave, idioma, licença",IF(AND($B5="Artigo",$E5=""),"Título em inglês obrigatório para artigo",IF(AND($M5="Outra — justificar",$N5=""),"Justificar a licença escolhida",IF(AND($P5="Embargo",$Q5=""),"Informar data de fim do embargo",IF($T5<>"Sim","Declarar ausência de dado pessoal identificável",IF($U5="Sim — vedado o depósito","Depósito vedado: contém dado sensível",IF(AND($B5="Conjunto de dados",$S5="Não se aplica"),"Conjunto de dados exige técnica de agregação declarada",IF($W5="Em preparação","Metadados ainda em preparação",IF(AND($W5="Publicado",$AA5=""),"Registrar o DOI de versão","Pronto para depósito")))))))))))
F6: Conselho Nacional de Desenvolvimento Científico e Tecnológico — CNPq | G6: PROSUL Pepe Mujica — Chamada MCTI/CNPq nº 02/2026, Faixa B | H6: 445280/2026-3 | O6: 1.0 | AB6: =IF(A6="","",IF(COUNTA($B6:$E6,$I6,$K6:$M6,$W6)=0,"Linha vazia",IF(COUNTA($B6:$E6,$I6,$K6:$M6)<8,"Campos obrigatórios pendentes: tipo, títulos PT/ES/EN, palavra-chave, idioma, licença",IF(AND($B6="Artigo",$E6=""),"Título em inglês obrigatório para artigo",IF(AND($M6="Outra — justificar",$N6=""),"Justificar a licença escolhida",IF(AND($P6="Embargo",$Q6=""),"Informar data de fim do embargo",IF($T6<>"Sim","Declarar ausência de dado pessoal identificável",IF($U6="Sim — vedado o depósito","Depósito vedado: contém dado sensível",IF(AND($B6="Conjunto de dados",$S6="Não se aplica"),"Conjunto de dados exige técnica de agregação declarada",IF($W6="Em preparação","Metadados ainda em preparação",IF(AND($W6="Publicado",$AA6=""),"Registrar o DOI de versão","Pronto para depósito")))))))))))
F7: Conselho Nacional de Desenvolvimento Científico e Tecnológico — CNPq | G7: PROSUL Pepe Mujica — Chamada MCTI/CNPq nº 02/2026, Faixa B | H7: 445280/2026-3 | O7: 1.0 | AB7: =IF(A7="","",IF(COUNTA($B7:$E7,$I7,$K7:$M7,$W7)=0,"Linha vazia",IF(COUNTA($B7:$E7,$I7,$K7:$M7)<8,"Campos obrigatórios pendentes: tipo, títulos PT/ES/EN, palavra-chave, idioma, licença",IF(AND($B7="Artigo",$E7=""),"Título em inglês obrigatório para artigo",IF(AND($M7="Outra — justificar",$N7=""),"Justificar a licença escolhida",IF(AND($P7="Embargo",$Q7=""),"Informar data de fim do embargo",IF($T7<>"Sim","Declarar ausência de dado pessoal identificável",IF($U7="Sim — vedado o depósito","Depósito vedado: contém dado sensível",IF(AND($B7="Conjunto de dados",$S7="Não se aplica"),"Conjunto de dados exige técnica de agregação declarada",IF($W7="Em preparação","Metadados ainda em preparação",IF(AND($W7="Publicado",$AA7=""),"Registrar o DOI de versão","Pronto para depósito")))))))))))
F8: Conselho Nacional de Desenvolvimento Científico e Tecnológico — CNPq | G8: PROSUL Pepe Mujica — Chamada MCTI/CNPq nº 02/2026, Faixa B | H8: 445280/2026-3 | O8: 1.0 | AB8: =IF(A8="","",IF(COUNTA($B8:$E8,$I8,$K8:$M8,$W8)=0,"Linha vazia",IF(COUNTA($B8:$E8,$I8,$K8:$M8)<8,"Campos obrigatórios pendentes: tipo, títulos PT/ES/EN, palavra-chave, idioma, licença",IF(AND($B8="Artigo",$E8=""),"Título em inglês obrigatório para artigo",IF(AND($M8="Outra — justificar",$N8=""),"Justificar a licença escolhida",IF(AND($P8="Embargo",$Q8=""),"Informar data de fim do embargo",IF($T8<>"Sim","Declarar ausência de dado pessoal identificável",IF($U8="Sim — vedado o depósito","Depósito vedado: contém dado sensível",IF(AND($B8="Conjunto de dados",$S8="Não se aplica"),"Conjunto de dados exige técnica de agregação declarada",IF($W8="Em preparação","Metadados ainda em preparação",IF(AND($W8="Publicado",$AA8=""),"Registrar o DOI de versão","Pronto para depósito")))))))))))
F9: Conselho Nacional de Desenvolvimento Científico e Tecnológico — CNPq | G9: PROSUL Pepe Mujica — Chamada MCTI/CNPq nº 02/2026, Faixa B | H9: 445280/2026-3 | O9: 1.0 | AB9: =IF(A9="","",IF(COUNTA($B9:$E9,$I9,$K9:$M9,$W9)=0,"Linha vazia",IF(COUNTA($B9:$E9,$I9,$K9:$M9)<8,"Campos obrigatórios pendentes: tipo, títulos PT/ES/EN, palavra-chave, idioma, licença",IF(AND($B9="Artigo",$E9=""),"Título em inglês obrigatório para artigo",IF(AND($M9="Outra — justificar",$N9=""),"Justificar a licença escolhida",IF(AND($P9="Embargo",$Q9=""),"Informar data de fim do embargo",IF($T9<>"Sim","Declarar ausência de dado pessoal identificável",IF($U9="Sim — vedado o depósito","Depósito vedado: contém dado sensível",IF(AND($B9="Conjunto de dados",$S9="Não se aplica"),"Conjunto de dados exige técnica de agregação declarada",IF($W9="Em preparação","Metadados ainda em preparação",IF(AND($W9="Publicado",$AA9=""),"Registrar o DOI de versão","Pronto para depósito")))))))))))
F10: Conselho Nacional de Desenvolvimento Científico e Tecnológico — CNPq | G10: PROSUL Pepe Mujica — Chamada MCTI/CNPq nº 02/2026, Faixa B | H10: 445280/2026-3 | O10: 1.0 | AB10: =IF(A10="","",IF(COUNTA($B10:$E10,$I10,$K10:$M10,$W10)=0,"Linha vazia",IF(COUNTA($B10:$E10,$I10,$K10:$M10)<8,"Campos obrigatórios pendentes: tipo, títulos PT/ES/EN, palavra-chave, idioma, licença",IF(AND($B10="Artigo",$E10=""),"Título em inglês obrigatório para artigo",IF(AND($M10="Outra — justificar",$N10=""),"Justificar a licença escolhida",IF(AND($P10="Embargo",$Q10=""),"Informar data de fim do embargo",IF($T10<>"Sim","Declarar ausência de dado pessoal identificável",IF($U10="Sim — vedado o depósito","Depósito vedado: contém dado sensível",IF(AND($B10="Conjunto de dados",$S10="Não se aplica"),"Conjunto de dados exige técnica de agregação declarada",IF($W10="Em preparação","Metadados ainda em preparação",IF(AND($W10="Publicado",$AA10=""),"Registrar o DOI de versão","Pronto para depósito")))))))))))
F11: Conselho Nacional de Desenvolvimento Científico e Tecnológico — CNPq | G11: PROSUL Pepe Mujica — Chamada MCTI/CNPq nº 02/2026, Faixa B | H11: 445280/2026-3 | O11: 1.0 | AB11: =IF(A11="","",IF(COUNTA($B11:$E11,$I11,$K11:$M11,$W11)=0,"Linha vazia",IF(COUNTA($B11:$E11,$I11,$K11:$M11)<8,"Campos obrigatórios pendentes: tipo, títulos PT/ES/EN, palavra-chave, idioma, licença",IF(AND($B11="Artigo",$E11=""),"Título em inglês obrigatório para artigo",IF(AND($M11="Outra — justificar",$N11=""),"Justificar a licença escolhida",IF(AND($P11="Embargo",$Q11=""),"Informar data de fim do embargo",IF($T11<>"Sim","Declarar ausência de dado pessoal identificável",IF($U11="Sim — vedado o depósito","Depósito vedado: contém dado sensível",IF(AND($B11="Conjunto de dados",$S11="Não se aplica"),"Conjunto de dados exige técnica de agregação declarada",IF($W11="Em preparação","Metadados ainda em preparação",IF(AND($W11="Publicado",$AA11=""),"Registrar o DOI de versão","Pronto para depósito")))))))))))
F12: Conselho Nacional de Desenvolvimento Científico e Tecnológico — CNPq | G12: PROSUL Pepe Mujica — Chamada MCTI/CNPq nº 02/2026, Faixa B | H12: 445280/2026-3 | O12: 1.0 | AB12: =IF(A12="","",IF(COUNTA($B12:$E12,$I12,$K12:$M12,$W12)=0,"Linha vazia",IF(COUNTA($B12:$E12,$I12,$K12:$M12)<8,"Campos obrigatórios pendentes: tipo, títulos PT/ES/EN, palavra-chave, idioma, licença",IF(AND($B12="Artigo",$E12=""),"Título em inglês obrigatório para artigo",IF(AND($M12="Outra — justificar",$N12=""),"Justificar a licença escolhida",IF(AND($P12="Embargo",$Q12=""),"Informar data de fim do embargo",IF($T12<>"Sim","Declarar ausência de dado pessoal identificável",IF($U12="Sim — vedado o depósito","Depósito vedado: contém dado sensível",IF(AND($B12="Conjunto de dados",$S12="Não se aplica"),"Conjunto de dados exige técnica de agregação declarada",IF($W12="Em preparação","Metadados ainda em preparação",IF(AND($W12="Publicado",$AA12=""),"Registrar o DOI de versão","Pronto para depósito")))))))))))
F13: Conselho Nacional de Desenvolvimento Científico e Tecnológico — CNPq | G13: PROSUL Pepe Mujica — Chamada MCTI/CNPq nº 02/2026, Faixa B | H13: 445280/2026-3 | O13: 1.0 | AB13: =IF(A13="","",IF(COUNTA($B13:$E13,$I13,$K13:$M13,$W13)=0,"Linha vazia",IF(COUNTA($B13:$E13,$I13,$K13:$M13)<8,"Campos obrigatórios pendentes: tipo, títulos PT/ES/EN, palavra-chave, idioma, licença",IF(AND($B13="Artigo",$E13=""),"Título em inglês obrigatório para artigo",IF(AND($M13="Outra — justificar",$N13=""),"Justificar a licença escolhida",IF(AND($P13="Embargo",$Q13=""),"Informar data de fim do embargo",IF($T13<>"Sim","Declarar ausência de dado pessoal identificável",IF($U13="Sim — vedado o depósito","Depósito vedado: contém dado sensível",IF(AND($B13="Conjunto de dados",$S13="Não se aplica"),"Conjunto de dados exige técnica de agregação declarada",IF($W13="Em preparação","Metadados ainda em preparação",IF(AND($W13="Publicado",$AA13=""),"Registrar o DOI de versão","Pronto para depósito")))))))))))

Sheet Autoria
A1: ID Interno do Produto | B1: Ordem de Autoria | C1: Nome Completo | D1: Instituição | E1: País | F1: ORCID | G1: Validação do ORCID | H1: Currículo Lattes | I1: Papel na Autoria | J1: Contribuição Declarada
G2: =IF($F2="","",IF(ISERROR(VALUE(MID(SUBSTITUTE($F2,"-",""),1,15))),"Caracteres inválidos",IF(LEN(SUBSTITUTE($F2,"-",""))<>16,"Formato: 0000-0000-0000-000X",IF(IF(MOD(12-MOD(SUMPRODUCT(--MID(SUBSTITUTE($F2,"-",""),ROW(INDIRECT("1:15")),1),2^(16-ROW(INDIRECT("1:15")))),11),11)=10,"X",TEXT(MOD(12-MOD(SUMPRODUCT(--MID(SUBSTITUTE($F2,"-",""),ROW(INDIRECT("1:15")),1),2^(16-ROW(INDIRECT("1:15")))),11),11),"0"))=RIGHT(SUBSTITUTE($F2,"-",""),1),"ORCID válido","Dígito verificador incorreto"))))
G3: =IF($F3="","",IF(ISERROR(VALUE(MID(SUBSTITUTE($F3,"-",""),1,15))),"Caracteres inválidos",IF(LEN(SUBSTITUTE($F3,"-",""))<>16,"Formato: 0000-0000-0000-000X",IF(IF(MOD(12-MOD(SUMPRODUCT(--MID(SUBSTITUTE($F3,"-",""),ROW(INDIRECT("1:15")),1),2^(16-ROW(INDIRECT("1:15")))),11),11)=10,"X",TEXT(MOD(12-MOD(SUMPRODUCT(--MID(SUBSTITUTE($F3,"-",""),ROW(INDIRECT("1:15")),1),2^(16-ROW(INDIRECT("1:15")))),11),11),"0"))=RIGHT(SUBSTITUTE($F3,"-",""),1),"ORCID válido","Dígito verificador incorreto"))))
G4: =IF($F4="","",IF(ISERROR(VALUE(MID(SUBSTITUTE($F4,"-",""),1,15))),"Caracteres inválidos",IF(LEN(SUBSTITUTE($F4,"-",""))<>16,"Formato: 0000-0000-0000-000X",IF(IF(MOD(12-MOD(SUMPRODUCT(--MID(SUBSTITUTE($F4,"-",""),ROW(INDIRECT("1:15")),1),2^(16-ROW(INDIRECT("1:15")))),11),11)=10,"X",TEXT(MOD(12-MOD(SUMPRODUCT(--MID(SUBSTITUTE($F4,"-",""),ROW(INDIRECT("1:15")),1),2^(16-ROW(INDIRECT("1:15")))),11),11),"0"))=RIGHT(SUBSTITUTE($F4,"-",""),1),"ORCID válido","Dígito verificador incorreto"))))
G5: =IF($F5="","",IF(ISERROR(VALUE(MID(SUBSTITUTE($F5,"-",""),1,15))),"Caracteres inválidos",IF(LEN(SUBSTITUTE($F5,"-",""))<>16,"Formato: 0000-0000-0000-000X",IF(IF(MOD(12-MOD(SUMPRODUCT(--MID(SUBSTITUTE($F5,"-",""),ROW(INDIRECT("1:15")),1),2^(16-ROW(INDIRECT("1:15")))),11),11)=10,"X",TEXT(MOD(12-MOD(SUMPRODUCT(--MID(SUBSTITUTE($F5,"-",""),ROW(INDIRECT("1:15")),1),2^(16-ROW(INDIRECT("1:15")))),11),11),"0"))=RIGHT(SUBSTITUTE($F5,"-",""),1),"ORCID válido","Dígito verificador incorreto"))))
G6: =IF($F6="","",IF(ISERROR(VALUE(MID(SUBSTITUTE($F6,"-",""),1,15))),"Caracteres inválidos",IF(LEN(SUBSTITUTE($F6,"-",""))<>16,"Formato: 0000-0000-0000-000X",IF(IF(MOD(12-MOD(SUMPRODUCT(--MID(SUBSTITUTE($F6,"-",""),ROW(INDIRECT("1:15")),1),2^(16-ROW(INDIRECT("1:15")))),11),11)=10,"X",TEXT(MOD(12-MOD(SUMPRODUCT(--MID(SUBSTITUTE($F6,"-",""),ROW(INDIRECT("1:15")),1),2^(16-ROW(INDIRECT("1:15")))),11),11),"0"))=RIGHT(SUBSTITUTE($F6,"-",""),1),"ORCID válido","Dígito verificador incorreto"))))
G7: =IF($F7="","",IF(ISERROR(VALUE(MID(SUBSTITUTE($F7,"-",""),1,15))),"Caracteres inválidos",IF(LEN(SUBSTITUTE($F7,"-",""))<>16,"Formato: 0000-0000-0000-000X",IF(IF(MOD(12-MOD(SUMPRODUCT(--MID(SUBSTITUTE($F7,"-",""),ROW(INDIRECT("1:15")),1),2^(16-ROW(INDIRECT("1:15")))),11),11)=10,"X",TEXT(MOD(12-MOD(SUMPRODUCT(--MID(SUBSTITUTE($F7,"-",""),ROW(INDIRECT("1:15")),1),2^(16-ROW(INDIRECT("1:15")))),11),11),"0"))=RIGHT(SUBSTITUTE($F7,"-",""),1),"ORCID válido","Dígito verificador incorreto"))))
G8: =IF($F8="","",IF(ISERROR(VALUE(MID(SUBSTITUTE($F8,"-",""),1,15))),"Caracteres inválidos",IF(LEN(SUBSTITUTE($F8,"-",""))<>16,"Formato: 0000-0000-0000-000X",IF(IF(MOD(12-MOD(SUMPRODUCT(--MID(SUBSTITUTE($F8,"-",""),ROW(INDIRECT("1:15")),1),2^(16-ROW(INDIRECT("1:15")))),11),11)=10,"X",TEXT(MOD(12-MOD(SUMPRODUCT(--MID(SUBSTITUTE($F8,"-",""),ROW(INDIRECT("1:15")),1),2^(16-ROW(INDIRECT("1:15")))),11),11),"0"))=RIGHT(SUBSTITUTE($F8,"-",""),1),"ORCID válido","Dígito verificador incorreto"))))
G9: =IF($F9="","",IF(ISERROR(VALUE(MID(SUBSTITUTE($F9,"-",""),1,15))),"Caracteres inválidos",IF(LEN(SUBSTITUTE($F9,"-",""))<>16,"Formato: 0000-0000-0000-000X",IF(IF(MOD(12-MOD(SUMPRODUCT(--MID(SUBSTITUTE($F9,"-",""),ROW(INDIRECT("1:15")),1),2^(16-ROW(INDIRECT("1:15")))),11),11)=10,"X",TEXT(MOD(12-MOD(SUMPRODUCT(--MID(SUBSTITUTE($F9,"-",""),ROW(INDIRECT("1:15")),1),2^(16-ROW(INDIRECT("1:15")))),11),11),"0"))=RIGHT(SUBSTITUTE($F9,"-",""),1),"ORCID válido","Dígito verificador incorreto"))))
G10: =IF($F10="","",IF(ISERROR(VALUE(MID(SUBSTITUTE($F10,"-",""),1,15))),"Caracteres inválidos",IF(LEN(SUBSTITUTE($F10,"-",""))<>16,"Formato: 0000-0000-0000-000X",IF(IF(MOD(12-MOD(SUMPRODUCT(--MID(SUBSTITUTE($F10,"-",""),ROW(INDIRECT("1:15")),1),2^(16-ROW(INDIRECT("1:15")))),11),11)=10,"X",TEXT(MOD(12-MOD(SUMPRODUCT(--MID(SUBSTITUTE($F10,"-",""),ROW(INDIRECT("1:15")),1),2^(16-ROW(INDIRECT("1:15")))),11),11),"0"))=RIGHT(SUBSTITUTE($F10,"-",""),1),"ORCID válido","Dígito verificador incorreto"))))
G11: =IF($F11="","",IF(ISERROR(VALUE(MID(SUBSTITUTE($F11,"-",""),1,15))),"Caracteres inválidos",IF(LEN(SUBSTITUTE($F11,"-",""))<>16,"Formato: 0000-0000-0000-000X",IF(IF(MOD(12-MOD(SUMPRODUCT(--MID(SUBSTITUTE($F11,"-",""),ROW(INDIRECT("1:15")),1),2^(16-ROW(INDIRECT("1:15")))),11),11)=10,"X",TEXT(MOD(12-MOD(SUMPRODUCT(--MID(SUBSTITUTE($F11,"-",""),ROW(INDIRECT("1:15")),1),2^(16-ROW(INDIRECT("1:15")))),11),11),"0"))=RIGHT(SUBSTITUTE($F11,"-",""),1),"ORCID válido","Dígito verificador incorreto"))))
G12: =IF($F12="","",IF(ISERROR(VALUE(MID(SUBSTITUTE($F12,"-",""),1,15))),"Caracteres inválidos",IF(LEN(SUBSTITUTE($F12,"-",""))<>16,"Formato: 0000-0000-0000-000X",IF(IF(MOD(12-MOD(SUMPRODUCT(--MID(SUBSTITUTE($F12,"-",""),ROW(INDIRECT("1:15")),1),2^(16-ROW(INDIRECT("1:15")))),11),11)=10,"X",TEXT(MOD(12-MOD(SUMPRODUCT(--MID(SUBSTITUTE($F12,"-",""),ROW(INDIRECT("1:15")),1),2^(16-ROW(INDIRECT("1:15")))),11),11),"0"))=RIGHT(SUBSTITUTE($F12,"-",""),1),"ORCID válido","Dígito verificador incorreto"))))
G13: =IF($F13="","",IF(ISERROR(VALUE(MID(SUBSTITUTE($F13,"-",""),1,15))),"Caracteres inválidos",IF(LEN(SUBSTITUTE($F13,"-",""))<>16,"Formato: 0000-0000-0000-000X",IF(IF(MOD(12-MOD(SUMPRODUCT(--MID(SUBSTITUTE($F13,"-",""),ROW(INDIRECT("1:15")),1),2^(16-ROW(INDIRECT("1:15")))),11),11)=10,"X",TEXT(MOD(12-MOD(SUMPRODUCT(--MID(SUBSTITUTE($F13,"-",""),ROW(INDIRECT("1:15")),1),2^(16-ROW(INDIRECT("1:15")))),11),11),"0"))=RIGHT(SUBSTITUTE($F13,"-",""),1),"ORCID válido","Dígito verificador incorreto"))))
... G31: =IF($F31="","",IF(ISERROR(VALUE(MID(SUBSTITUTE($F31,"-",""),1,15))),"Caracteres inválidos",IF(LEN(SUBSTITUTE($F31,"-",""))<>16,"Formato: 0000-0000-0000-000X",IF(IF(MOD(12-MOD(SUMPRODUCT(--MID(SUBSTITUTE($F31,"-",""),ROW(INDIRECT("1:15")),1),2^(16-ROW(INDIRECT("1:15")))),11),11)=10,"X",TEXT(MOD(12-MOD(SUMPRODUCT(--MID(SUBSTITUTE($F31,"-",""),ROW(INDIRECT("1:15")),1),2^(16-ROW(INDIRECT("1:15")))),11),11),"0"))=RIGHT(SUBSTITUTE($F31,"-",""),1),"ORCID válido","Dígito verificador incorreto"))))

Sheet Validação
A1: Indicador | B1: Resultado
A2: Produtos cadastrados | B2: =COUNTA('Ficha de Depósito'!A2:A13)
A3: Prontos para depósito | B3: =COUNTIF('Ficha de Depósito'!AB2:AB13,"Pronto para depósito")
A4: Em preparação | B4: =COUNTIF('Ficha de Depósito'!AB2:AB13,"Metadados ainda em preparação")
A5: Bloqueados ou vedados | B5: =COUNTIF('Ficha de Depósito'!AB2:AB13,"*vedado*")+COUNTIF('Ficha de Depósito'!AB2:AB13,"*Bloqueado*")
A6: Total de autorias registradas | B6: =COUNTA(Autoria!C2:C31)
A7: ORCIDs válidos | B7: =COUNTIF(Autoria!G2:G31,"ORCID válido")
A8: ORCIDs inválidos | B8: =COUNTIF(Autoria!G2:G31,"Dígito verificador incorreto")+COUNTIF(Autoria!G2:G31,"Caracteres inválidos")+COUNTIF(Autoria!G2:G31,"Formato: 0000-0000-0000-000X")
A9: Autoria sem ORCID preenchido | B9: =COUNTIFS(Autoria!C2:C31,"<>",Autoria!F2:F31,"")
A10: Produtos depositados sem DOI conceito | B10: =COUNTIFS('Ficha de Depósito'!W2:W13,"Depositado",'Ficha de Depósito'!Z2:Z13,"")+COUNTIFS('Ficha de Depósito'!W2:W13,"Publicado",'Ficha de Depósito'!Z2:Z13,"")
A11: Produtos publicados sem DOI de versão | B11: =COUNTIFS('Ficha de Depósito'!W2:W13,"Publicado",'Ficha de Depósito'!AA2:AA13,"")
A12: Percentual de completude da ficha (meta: 100%) | B12: =IFERROR(ROUND(COUNTIF('Ficha de Depósito'!AB2:AB13,"Pronto para depósito")/COUNTA('Ficha de Depósito'!A2:A13),4),0)
A14: Enquanto 'ORCIDs inválidos' ou 'Autoria sem ORCID preenchido' forem maiores que zero, o depósito não deve ser realizado. O ORCID é o vínculo entre a autoria e o produto no ecossistema acadêmico.

Sheet Diretório de Autoria
A1: Nome Completo | B1: Instituição | C1: País | D1: ORCID | E1: Lattes ou perfil | F1: Validação do ORCID
A2: Adriana Cuartas | B2: Cemaden/MCTI | C2: Brasil | D2: 0000-0001-8993-5985 | F2: ORCID válido
A3: Allan Yu Iwama | B3: Cemaden/MCTI | C3: Brasil | D3: 0000-0003-1707-8392 | F3: ORCID válido
A4: Ana Paula Martins do Amaral Cunha | B4: Cemaden/MCTI | C4: Brasil | D4: 0000-0002-9924-6523 | F4: ORCID válido
A5: Andrezza Mafer | B5: Cemaden/MCTI | C5: Brasil | E5: http://lattes.cnpq.br/3558999164415375
A6: Cintya Azambuja Martins | B6: UFOPA | C6: Brasil | E6: https://lattes.cnpq.br/6344891620719570
A7: Danyelle Stringari | B7: UNESPAR/CEPED-PR | C7: Brasil | E7: http://lattes.cnpq.br/6235127981805861
A8: Felipe Augusto Santos | B8: Cemaden/MCTI / UNESP | C8: Brasil | E8: http://lattes.cnpq.br/1658250368047614
A9: Elisabete Weber Reckziegel | B9: Cemaden/MCTI | C9: Brasil | E9: http://lattes.cnpq.br/3280250811525994
A10: Gisele dos Santos Zepka Saraiva | B10: Cemaden/MCTI | C10: Brasil | E10: http://lattes.cnpq.br/6226055129974273
A11: Graziela Scofield | B11: Cemaden/MCTI | C11: Brasil | E11: http://lattes.cnpq.br/8648556155554795
A12: Leda Nardi | B12: UNESP | C12: Brasil | E12: http://lattes.cnpq.br/2979501883053251
A13: Luciana R. Londe | B13: Cemaden/MCTI | C13: Brasil | D13: 0000-0002-6494-0486 | F13: ORCID válido
A14: Magali Zilca Dantas | B14: ENAP | C14: Brasil | E14: http://lattes.cnpq.br/4640057018663796
A15: Pamela Mércia Pinto Gomes | B15: Instituto TJNS / UFRJ | C15: Brasil | E15: http://lattes.cnpq.br/9810502689021007
A16: Rebecca Luna Lucena | B16: UFRN | C16: Brasil | D16: 0000-0003-4670-265X | F16: ORCID válido
A17: Regla Somoza | B17: Cemaden/MCTI | C17: Brasil | E17: http://lattes.cnpq.br/1010059005093122
A18: Rodrigo Silva da Conceição | B18: Cemaden/MCTI | C18: Brasil | E18: http://lattes.cnpq.br/6765553122333119
A19: Rosinadja B. Morato | B19: IBGE | C19: Brasil | D19: 0000-0002-0160-8478 | F19: ORCID válido
A20: Sara Fernandes Flor de Souza | B20: UFRN | C20: Brasil | D20: 0000-0001-6829-3434 | F20: ORCID válido
A21: Silvia Saito | B21: Cemaden/MCTI | C21: Brasil | E21: http://lattes.cnpq.br/6697221737762500
A22: Suzana Maria Gico Lima Montenegro | B22: UFPE | C22: Brasil | D22: 0000-0002-2520-5761 | F22: ORCID válido
A23: Vanessa de Souza Hacon | B23: Ministério da Saúde | C23: Brasil | E23: http://lattes.cnpq.br/4546171962465390
A24: Viviana Aguilar-Muñoz | B24: Cemaden/MCTI | C24: Brasil | D24: 0000-0002-2899-8082 | F24: ORCID válido
A25: María Natalia Echegoyemberry | B25: XUMEK / Observatório de Justiça Sanitária e Climática | C25: Argentina | D25: 0000-0001-9049-8233 | F25: ORCID válido
A26: Ana Isabel Huaico | B26: UTEM | C26: Chile | D26: 0000-0001-7368-0455 | F26: ORCID válido
A27: Claudia C. Becerra | B27: GRID Chile | C27: Chile
A28: Drielly Naamma Fonseca da Silva | B28: UTEM | C28: Chile | D28: 0000-0002-1374-8697 | F28: ORCID válido
A29: Keyla Manuela Alencar da Silva Alves | B29: UTEM | C29: Chile | D29: 0000-0001-7635-2430 | F29: ORCID válido
A30: Rayana Santos Araújo Palharini | B30: UTEM | C30: Chile | D30: 0000-0001-5503-8450 | F30: ORCID válido
A31: Daniel López de Mesa Aguilar | B31: Universidad de Medellín | C31: Colômbia | D31: 0000-0002-7577-5527 | F31: ORCID válido
A32: Diana Elizabeth Valencia Londoño | B32: Universidad de San Buenaventura | C32: Colômbia | D32: 0000-0002-4542-4128 | F32: ORCID válido
A33: Diana Patricia Mendoza Gonzalez | B33: Pesquisadora independente | C33: Colômbia | D33: 0000-0002-9961-1025 | F33: ORCID válido
A34: Janet Barco | B34: Pesquisadora independente | C34: Colômbia | D34: 0000-0003-3919-0027 | F34: ORCID válido
A35: Johnny Alexander Vega Gutiérrez | B35: Universidad de Medellín | C35: Colômbia | D35: 0000-0002-0662-7213 | F35: ORCID válido
A36: Natalia María Posada Pérez | B36: Colegio Mayor de Antioquia | C36: Colômbia | D36: 0000-0002-1853-2377 | F36: ORCID válido
A37: Paula Andrea Valencia Londoño | B37: Universidad de Medellín | C37: Colômbia | D37: 0000-0002-1077-6959 | F37: ORCID válido
A38: Sara Andrea Giraldo Arias | B38: OPI4 | C38: Colômbia | E38: https://www.linkedin.com/in/saragiraldoarias
A39: Jazmín Calderón Quirós | B39: CeNAT/LANBA | C39: Costa Rica | D39: 0000-0001-8316-1835 | F39: ORCID válido
A40: Jeannette Arauz Muñoz | B40: CeNAT/LANBA | C40: Costa Rica | D40: 0000-0002-9867-6855 | F40: ORCID válido
...

Sheet Vocabulário Controlado
A1: Tipo de Recurso | B1: Idioma | C1: Licença | D1: Palavra-chave Principal | E1: Técnica de Agregação | F1: Status do Fluxo | G1: Papel na Autoria | H1: Papel na Autoria
A2: Artigo | B2: Português | C2: CC BY 4.0 | D2: Interseccionalidade | E2: Não se aplica | F2: Em preparação | G2: Brasil | H2: Concepção
A3: Relatório técnico | B3: Espanhol | C3: CC BY-SA 4.0 | D3: Justiça climática | E3: Agregação por setor censitário | F3: Metadados completos | G3: Argentina | H3: Dados
A4: Conjunto de dados | B4: Inglês | C4: CC BY-NC 4.0 | D4: Redução de riscos de desastres | E4: Supressão de células pequenas | F4: Depositado | G4: Chile | H4: Redação
A5: Material de formação | B5: Português e Espanhol | C5: CC0 1.0 | D5: Gênero e desastres | E5: Anonimização | F5: Publicado | G5: Colômbia | H5: Revisão crítica
A6: Protocolo | B6: Multilíngue com língua originária | C6: Outra — justificar | D6: Racismo ambiental | E6: Agregação por município | F6: Bloqueado | G6: Costa Rica | H6: Coordenação
A7: Software | D7: Vulnerabilidade social | G7: Equador | H7: Análise de dados
D8: Impact-based forecasting | G8: Panamá | H8: Trabalho de campo
D9: Protocolos decoloniais | G9: Peru
D10: SoVI-I ALC | G10: Uruguai | H10: Sim
D11: BATER-ALC | H11: Não — revisar antes do depósito
D12: Índice de Inclusão Interseccional
D13: Dados censitários | H13: Não
D14: Povos indígenas | H14: Sim — vedado o depósito
D15: Segurança hídrica
D16: Saúde pública e clima
D17: Comunicação de risco
A19: Vocabulário Controlado — versão 1.1 · outubro de 2026. A versão trilíngue definitiva, com 65 termos em 11 domínios, definições e relações de tesauro em português, espanhol e inglês, está na aba 'Vocabulário PT-ES-EN'. As listas desta aba permanecem como fonte técnica das validações de dados das abas 'Ficha de Depósito' e 'Autoria'. Mapa de aplicação campo a campo na aba 'Mapa de Uso'. Aprovação formal pendente do Comitê Gestor Interinstitucional.

Sheet Vocabulário PT-ES-EN
A1: Vocabulário Controlado da Rede Interseccional de Resiliência — versão trilíngue
A2: Versão 1.0 · Outubro de 2026 · 65 termos em 11 domínios · Português, Español, English
A3: Escopo: termos de indexação, classificação e preenchimento de metadados nos depósitos da Rede no Zenodo.
A4: Status geral: proposto para aprovação do Comitê Gestor Interinstitucional (CGI). A aprovação formal pelo CGI é o ato que torna esta versão vinculante. Até lá, os termos abaixo já podem ser usados operacionalmente.
A5: Regra de uso: termos preferenciais devem ser grafados exatamente como na coluna do idioma correspondente. Sinônimos listados na coluna 'USE FOR' não devem ser usados como termo de indexação.
A6: Modelo de governança: alterações exigem justificativa registrada, versão incrementada e aprovação do CGI. O domínio 'Palavra-chave Principal' segue a lógica de um tesauro: termo geral (TG) e termos específicos (TE) indicam relações hierárquicas.
A8: ID | B8: Domínio | C8: Termo PT (preferencial) | D8: Término ES (preferente) | E8: Preferred term EN | F8: Definição PT | G8: Definición ES | H8: Definition EN | I8: USE FOR / sinônimos (PT) | J8: TG — termo geral | K8: TE — termos específicos | L8: Fonte de referência | M8: Status | N8: Observações de uso
A9: VC-TR-01 | B9: Tipo de Recurso | C9: Artigo | D9: Artículo | E9: Article | F9: Manuscrito publicado ou aceito em periódico com revisão por pares. | G9: Manuscrito publicado o aceptado en revista con revisión por pares. | H9: Manuscript published or accepted in a peer-reviewed journal. | I9: Trabalho completo; Paper | J9: — | K9: — | L9: — | M9: Proposto | N9: DOI obrigatório antes da divulgação.
A10: VC-TR-02 | B10: Tipo de Recurso | C10: Relatório técnico | D10: Informe técnico | E10: Technical report | F10: Documento de sistematização, protocolo ou resultado de projeto, sem revisão por pares. | G10: Documento de sistematización, protocolo o resultado de proyecto, sin revisión por pares. | H10: Systematization document, protocol or project result, without peer review. | I10: Relatório de projeto; Produto técnico | J10: — | K10: — | L10: — | M10: Proposto | N10: Exige leitura crítica de instituição de país distinto.
A11: VC-TR-03 | B11: Tipo de Recurso | C11: Conjunto de dados | D11: Conjunto de datos | E11: Dataset | F11: Coleção estruturada de dados depositada com metadados que permitem reuso por terceiros. | G11: Colección estructurada de datos depositada con metadatos que permiten su reutilización por terceros. | H11: Structured data collection deposited with metadata enabling third-party reuse. | I11: Base de dados; Dataset | J11: — | K11: — | L11: — | M11: Proposto | N11: Sempre acompanhado de declaração da técnica de agregação.
A12: VC-TR-04 | B12: Tipo de Recurso | C12: Material de formação | D12: Material de formación | E12: Training material | F12: Conteúdo pedagógico destinado à capacitação de multiplicadores, gestores ou comunidades. | G12: Contenido pedagógico destinado a la capacitación de multiplicadores, gestores o comunidades. | H12: Educational content for training multipliers, managers or communities. | I12: Cartilha; Kit; Material didático | J12: — | K12: — | L12: — | M12: Proposto | N12: Incluir versão em língua originária quando aplicável.
A13: VC-TR-05 | B13: Tipo de Recurso | C13: Protocolo | D13: Protocolo | E13: Protocol | F13: Procedimento operacional documentado, validado e versionado para aplicação em território. | G13: Procedimiento operativo documentado, validado y versionado para aplicación en territorio. | H13: Documented, validated and versioned operating procedure for field application. | I13: Protocolo operacional; POP | J13: — | K13: — | L13: — | M13: Proposto | N13: Exige registro da validação com lideranças locais.
A14: VC-TR-06 | B14: Tipo de Recurso | C14: Software | D14: Software | E14: Software | F14: Código executável, script ou aplicativo depositado com documentação de uso e dependências. | G14: Código ejecutable, script o aplicación depositada con documentación de uso y dependencias. | H14: Executable code, script or application deposited with usage documentation and dependencies. | I14: Script; Código; Aplicativo | J14: — | K14: — | L14: — | M14: Proposto | N14: Declarar licença de software separadamente da licença do conteúdo.
A15: VC-ID-01 | B15: Idioma | C15: Português | D15: Portugués | E15: Portuguese | F15: Idioma do arquivo ou dos metadados em português. | G15: Idioma del archivo o de los metadatos en portugués. | H15: Language of the file or metadata in Portuguese. | I15: PT | J15: — | K15: — | L15: ISO 639-1: pt | M15: Proposto | N15: —
A16: VC-ID-02 | B16: Idioma | C16: Espanhol | D16: Español | E16: Spanish | F16: Idioma do arquivo ou dos metadados em espanhol. | G16: Idioma del archivo o de los metadatos en español. | H16: Language of the file or metadata in Spanish. | I16: ES; Castelhano | J16: — | K16: — | L16: ISO 639-1: es | M16: Proposto | N16: Língua de trabalho de oito dos nove países da Rede.
A17: VC-ID-03 | B17: Idioma | C17: Inglês | D17: Inglés | E17: English | F17: Idioma do arquivo ou dos metadados em inglês. | G17: Idioma del archivo o de los metadatos en inglés. | H17: Language of the file or metadata in English. | I17: EN | J17: — | K17: — | L17: ISO 639-1: en | M17: Proposto | N17: Obrigatório no título apenas para Artigo.
A18: VC-ID-04 | B18: Idioma | C18: Português e Espanhol | D18: Portugués y español | E18: Portuguese and Spanish | F18: Arquivo bilíngue, com o mesmo conteúdo em português e espanhol. | G18: Archivo bilingüe, con el mismo contenido en portugués y español. | H18: Bilingual file with the same content in Portuguese and Spanish. | I18: Bilíngue PT-ES | J18: — | K18: — | L18: — | M18: Proposto | N18: Preferencial para produtos de alcance regional.
A19: VC-ID-05 | B19: Idioma | C19: Multilíngue com língua originária | D19: Multilingüe con lengua originaria | E19: Multilingual with Indigenous language | F19: Arquivo que inclui, além de português ou espanhol, uma língua originária. | G19: Archivo que incluye, además de portugués o español, una lengua originaria. | H19: File including, besides Portuguese or Spanish, an Indigenous language. | I19: Quíchua; Aimará; Língua indígena | J19: — | K19: — | L19: — | M19: Proposto | N19: Declarar no metadado qual língua originária foi utilizada.
... A73: VC-PS-09 | B73: País | C73: Uruguai | D73: Uruguay | E73: Uruguay | F73: República Oriental do Uruguai. | G73: República Oriental del Uruguay. | H73: Oriental Republic of Uruguay. | I73: UY | J73: — | K73: — | L73: ISO 3166-1: UY | M73: Proposto | N73: —

Sheet Mapa de Uso
A1: Mapa de Uso do Vocabulário Controlado
A3: Domínio | B3: Aba de destino | C3: Coluna | D3: Campo de destino | E3: Obrigatoriedade | F3: Observação de manutenção
A4: Tipo de Recurso | B4: Ficha de Depósito | C4: B | D4: Tipo de Recurso | E4: Obrigatório | F4: Alterar a lista exige atualizar a validação da coluna B.
A5: Idioma | B5: Ficha de Depósito | C5: K | D5: Idioma do Arquivo | E5: Obrigatório | F5: —
A6: Idioma | B6: Ficha de Depósito | C6: L | D6: Idioma dos Metadados | E6: Obrigatório | F6: —
A7: Licença | B7: Ficha de Depósito | C7: M | D7: Licença | E7: Obrigatório | F7: "Outra — justificar" aciona a coluna N.
A8: Acesso | B8: Ficha de Depósito | C8: P | D8: Acesso | E8: Obrigatório | F8: "Embargo" aciona a coluna Q.
A9: Técnica de Agregação | B9: Ficha de Depósito | C9: S | D9: Técnica de Agregação | E9: Condicional | F9: Obrigatória apenas quando o tipo for Conjunto de dados.
A10: Status do Fluxo | B10: Ficha de Depósito | C10: W | D10: Status do Fluxo | E10: Obrigatório | F10: Governa a conferência automática da coluna AB.
A11: Palavra-chave Principal | B11: Ficha de Depósito | C11: I | D11: Palavra-chave Principal | E11: Obrigatório | F11: Apenas um termo principal por produto; adicionais na coluna J em texto livre.
A12: Declaração de Dado Pessoal | B12: Ficha de Depósito | C12: T | D12: Declara Ausência de Dado Pessoal Identificável | E12: Obrigatório | F12: "Não" bloqueia a conferência automática.
A13: Declaração de Dado Sensível | B13: Ficha de Depósito | C13: U | D13: Contém Dado Sensível | E13: Obrigatório | F13: "Sim" impede o depósito.
A14: Papel na Autoria | B14: Autoria | C14: I | D14: Papel na Autoria | E14: Obrigatório | F14: Uma pessoa pode acumular mais de um papel em linhas distintas.
... A16: País | B16: Diretório de Autoria | C16: C | D16: País | E16: Obrigatório | F16: Manter sincronizado com a aba Autoria.
A18: Regra de manutenção: qualquer inclusão, exclusão ou alteração de termo deve ser registrada com data, responsável e justificativa, gerar incremento de versão menor (1.0 para 1.1) e ser submetida ao Comitê Gestor Interinstitucional antes de entrar em uso.

Sheet Fluxo de Depósito
A1: Etapa | B1: Descrição | C1: Responsável | D1: Concluído (Sim/Não) | E1: Data | F1: Observações | G1: Validação
A2: 1. Qualificação do produto | B2: Definir tipo e verificar se há dado pessoal, sensível ou passível de identificação indireta | G2: =IF(D2="Sim","Etapa concluída","Pendente")
A3: 2. Verificação de ética e LGPD | B3: Conferir parecer do Sistema CEP/CONEP; garantir agregação ou anonimização de dados primários | G3: =IF(D3="Sim","Etapa concluída","Pendente")
A4: 3. Preparação dos metadados | B4: Preencher a aba Ficha de Depósito e registrar toda a autoria na aba Autoria | G4: =IF(D4="Sim","Etapa concluída","Pendente")
A5: 4. Depósito no Zenodo | B5: Criar o registro, carregar arquivos, vincular ao projeto, obter DOI conceito e DOI de versão | G5: =IF(D5="Sim","Etapa concluída","Pendente")
A6: 5. Publicação e vinculação | B6: Liberar o registro, atualizar a página Produção e dados, o ORCID de cada autoria e o Currículo Lattes, e registrar no relatório do CNPq | G6: =IF(D6="Sim","Etapa concluída","Pendente")
